{'activation': 'relu', 'dropout': 0.6413276178, 'hist_agg': 'none', 'layers': 3, 'learning_method': 'rmsprop', 'lr': 0.0064259937, 'n_cases': 24160, 'n_features': 260, 'n_games': 4, 'steps': 700, 'units': 35}
(sqlite3.OperationalError) unable to open database file (Background on this error at: http://sqlalche.me/e/e3q8)
['  File "scripts/meval.sc", line 3, in <module>\n    do_meval.process_cmd_line()\n', '  File "/home/delano/working/python_misc/ledona/__init__.py", line 19, in wrapper\n    result = timed_func(*args, **kwargs)\n', '  File "/home/delano/working/fantasy/fantasy_py/calculation/regression/exe/do_meval.py", line 562, in process_cmd_line\n    result = calc_engine.run_evaluation(eval_func)\n', '  File "/home/delano/working/fantasy/fantasy_py/calculation/engine.py", line 776, in run_evaluation\n    calc_def_id=calc_def_id)\n', '  File "/home/delano/working/fantasy/fantasy_py/calculation/engine.py", line 756, in calculate\n    **extra_kwargs)\n', '  File "/home/delano/working/fantasy/fantasy_py/calculation/regression/exe/do_meval.py", line 470, in eval_func\n    \'db\': meta_info.db_path.split(os.sep)[-1]})\n', '  File "/home/delano/working/fantasy/fantasy_py/util/hyper_param_tuning.py", line 893, in search\n    n_calls=self._iterations, n_random_starts=self._bayes_init_pts)\n', '  File "/home/delano/working/fantasy/venv/lib/python3.6/site-packages/skopt/optimizer/gp.py", line 228, in gp_minimize\n    callback=callback, n_jobs=n_jobs)\n', '  File "/home/delano/working/fantasy/venv/lib/python3.6/site-packages/skopt/optimizer/base.py", line 248, in base_minimize\n    next_y = func(next_x)\n', '  File "/home/delano/working/fantasy/fantasy_py/util/hyper_param_tuning.py", line 869, in skopt_func\n    self.errors[flattened_hp_dict] = (ex, traceback.format_stack())\n']
----------------------------------------


{'activation': 'relu', 'dropout': 0.6513816568, 'hist_agg': 'none', 'layers': 3, 'learning_method': 'rmsprop', 'lr': 0.006311684, 'n_cases': 23587, 'n_features': 260, 'n_games': 4, 'steps': 700, 'units': 34}
(sqlite3.OperationalError) unable to open database file (Background on this error at: http://sqlalche.me/e/e3q8)
['  File "scripts/meval.sc", line 3, in <module>\n    do_meval.process_cmd_line()\n', '  File "/home/delano/working/python_misc/ledona/__init__.py", line 19, in wrapper\n    result = timed_func(*args, **kwargs)\n', '  File "/home/delano/working/fantasy/fantasy_py/calculation/regression/exe/do_meval.py", line 562, in process_cmd_line\n    result = calc_engine.run_evaluation(eval_func)\n', '  File "/home/delano/working/fantasy/fantasy_py/calculation/engine.py", line 776, in run_evaluation\n    calc_def_id=calc_def_id)\n', '  File "/home/delano/working/fantasy/fantasy_py/calculation/engine.py", line 756, in calculate\n    **extra_kwargs)\n', '  File "/home/delano/working/fantasy/fantasy_py/calculation/regression/exe/do_meval.py", line 470, in eval_func\n    \'db\': meta_info.db_path.split(os.sep)[-1]})\n', '  File "/home/delano/working/fantasy/fantasy_py/util/hyper_param_tuning.py", line 893, in search\n    n_calls=self._iterations, n_random_starts=self._bayes_init_pts)\n', '  File "/home/delano/working/fantasy/venv/lib/python3.6/site-packages/skopt/optimizer/gp.py", line 228, in gp_minimize\n    callback=callback, n_jobs=n_jobs)\n', '  File "/home/delano/working/fantasy/venv/lib/python3.6/site-packages/skopt/optimizer/base.py", line 248, in base_minimize\n    next_y = func(next_x)\n', '  File "/home/delano/working/fantasy/fantasy_py/util/hyper_param_tuning.py", line 869, in skopt_func\n    self.errors[flattened_hp_dict] = (ex, traceback.format_stack())\n']
----------------------------------------


{'activation': 'relu', 'dropout': 0.6476867368, 'hist_agg': 'none', 'layers': 2, 'learning_method': 'rmsprop', 'lr': 0.0066625699, 'n_cases': 25928, 'n_features': 132, 'n_games': 2, 'steps': 400, 'units': 35}
(sqlite3.OperationalError) unable to open database file (Background on this error at: http://sqlalche.me/e/e3q8)
['  File "scripts/meval.sc", line 3, in <module>\n    do_meval.process_cmd_line()\n', '  File "/home/delano/working/python_misc/ledona/__init__.py", line 19, in wrapper\n    result = timed_func(*args, **kwargs)\n', '  File "/home/delano/working/fantasy/fantasy_py/calculation/regression/exe/do_meval.py", line 562, in process_cmd_line\n    result = calc_engine.run_evaluation(eval_func)\n', '  File "/home/delano/working/fantasy/fantasy_py/calculation/engine.py", line 776, in run_evaluation\n    calc_def_id=calc_def_id)\n', '  File "/home/delano/working/fantasy/fantasy_py/calculation/engine.py", line 756, in calculate\n    **extra_kwargs)\n', '  File "/home/delano/working/fantasy/fantasy_py/calculation/regression/exe/do_meval.py", line 470, in eval_func\n    \'db\': meta_info.db_path.split(os.sep)[-1]})\n', '  File "/home/delano/working/fantasy/fantasy_py/util/hyper_param_tuning.py", line 893, in search\n    n_calls=self._iterations, n_random_starts=self._bayes_init_pts)\n', '  File "/home/delano/working/fantasy/venv/lib/python3.6/site-packages/skopt/optimizer/gp.py", line 228, in gp_minimize\n    callback=callback, n_jobs=n_jobs)\n', '  File "/home/delano/working/fantasy/venv/lib/python3.6/site-packages/skopt/optimizer/base.py", line 248, in base_minimize\n    next_y = func(next_x)\n', '  File "/home/delano/working/fantasy/fantasy_py/util/hyper_param_tuning.py", line 869, in skopt_func\n    self.errors[flattened_hp_dict] = (ex, traceback.format_stack())\n']
----------------------------------------


{'activation': 'relu', 'dropout': 0.4078306417, 'hist_agg': 'none', 'layers': 3, 'learning_method': 'rmsprop', 'lr': 0.0075796442, 'n_cases': 12267, 'n_features': 260, 'n_games': 4, 'steps': 700, 'units': 35}
(sqlite3.OperationalError) unable to open database file (Background on this error at: http://sqlalche.me/e/e3q8)
['  File "scripts/meval.sc", line 3, in <module>\n    do_meval.process_cmd_line()\n', '  File "/home/delano/working/python_misc/ledona/__init__.py", line 19, in wrapper\n    result = timed_func(*args, **kwargs)\n', '  File "/home/delano/working/fantasy/fantasy_py/calculation/regression/exe/do_meval.py", line 562, in process_cmd_line\n    result = calc_engine.run_evaluation(eval_func)\n', '  File "/home/delano/working/fantasy/fantasy_py/calculation/engine.py", line 776, in run_evaluation\n    calc_def_id=calc_def_id)\n', '  File "/home/delano/working/fantasy/fantasy_py/calculation/engine.py", line 756, in calculate\n    **extra_kwargs)\n', '  File "/home/delano/working/fantasy/fantasy_py/calculation/regression/exe/do_meval.py", line 470, in eval_func\n    \'db\': meta_info.db_path.split(os.sep)[-1]})\n', '  File "/home/delano/working/fantasy/fantasy_py/util/hyper_param_tuning.py", line 893, in search\n    n_calls=self._iterations, n_random_starts=self._bayes_init_pts)\n', '  File "/home/delano/working/fantasy/venv/lib/python3.6/site-packages/skopt/optimizer/gp.py", line 228, in gp_minimize\n    callback=callback, n_jobs=n_jobs)\n', '  File "/home/delano/working/fantasy/venv/lib/python3.6/site-packages/skopt/optimizer/base.py", line 248, in base_minimize\n    next_y = func(next_x)\n', '  File "/home/delano/working/fantasy/fantasy_py/util/hyper_param_tuning.py", line 869, in skopt_func\n    self.errors[flattened_hp_dict] = (ex, traceback.format_stack())\n']
----------------------------------------


{'activation': 'relu', 'dropout': 0.6513545432, 'hist_agg': 'none', 'layers': 3, 'learning_method': 'rmsprop', 'lr': 0.0062313495, 'n_cases': 19844, 'n_features': 260, 'n_games': 4, 'steps': 700, 'units': 33}
(sqlite3.OperationalError) unable to open database file (Background on this error at: http://sqlalche.me/e/e3q8)
['  File "scripts/meval.sc", line 3, in <module>\n    do_meval.process_cmd_line()\n', '  File "/home/delano/working/python_misc/ledona/__init__.py", line 19, in wrapper\n    result = timed_func(*args, **kwargs)\n', '  File "/home/delano/working/fantasy/fantasy_py/calculation/regression/exe/do_meval.py", line 562, in process_cmd_line\n    result = calc_engine.run_evaluation(eval_func)\n', '  File "/home/delano/working/fantasy/fantasy_py/calculation/engine.py", line 776, in run_evaluation\n    calc_def_id=calc_def_id)\n', '  File "/home/delano/working/fantasy/fantasy_py/calculation/engine.py", line 756, in calculate\n    **extra_kwargs)\n', '  File "/home/delano/working/fantasy/fantasy_py/calculation/regression/exe/do_meval.py", line 470, in eval_func\n    \'db\': meta_info.db_path.split(os.sep)[-1]})\n', '  File "/home/delano/working/fantasy/fantasy_py/util/hyper_param_tuning.py", line 893, in search\n    n_calls=self._iterations, n_random_starts=self._bayes_init_pts)\n', '  File "/home/delano/working/fantasy/venv/lib/python3.6/site-packages/skopt/optimizer/gp.py", line 228, in gp_minimize\n    callback=callback, n_jobs=n_jobs)\n', '  File "/home/delano/working/fantasy/venv/lib/python3.6/site-packages/skopt/optimizer/base.py", line 248, in base_minimize\n    next_y = func(next_x)\n', '  File "/home/delano/working/fantasy/fantasy_py/util/hyper_param_tuning.py", line 869, in skopt_func\n    self.errors[flattened_hp_dict] = (ex, traceback.format_stack())\n']
----------------------------------------


{'activation': 'relu', 'dropout': 0.6450825861, 'hist_agg': 'none', 'layers': 3, 'learning_method': 'rmsprop', 'lr': 0.006256204, 'n_cases': 24166, 'n_features': 260, 'n_games': 4, 'steps': 500, 'units': 36}
(sqlite3.OperationalError) unable to open database file (Background on this error at: http://sqlalche.me/e/e3q8)
['  File "scripts/meval.sc", line 3, in <module>\n    do_meval.process_cmd_line()\n', '  File "/home/delano/working/python_misc/ledona/__init__.py", line 19, in wrapper\n    result = timed_func(*args, **kwargs)\n', '  File "/home/delano/working/fantasy/fantasy_py/calculation/regression/exe/do_meval.py", line 562, in process_cmd_line\n    result = calc_engine.run_evaluation(eval_func)\n', '  File "/home/delano/working/fantasy/fantasy_py/calculation/engine.py", line 776, in run_evaluation\n    calc_def_id=calc_def_id)\n', '  File "/home/delano/working/fantasy/fantasy_py/calculation/engine.py", line 756, in calculate\n    **extra_kwargs)\n', '  File "/home/delano/working/fantasy/fantasy_py/calculation/regression/exe/do_meval.py", line 470, in eval_func\n    \'db\': meta_info.db_path.split(os.sep)[-1]})\n', '  File "/home/delano/working/fantasy/fantasy_py/util/hyper_param_tuning.py", line 893, in search\n    n_calls=self._iterations, n_random_starts=self._bayes_init_pts)\n', '  File "/home/delano/working/fantasy/venv/lib/python3.6/site-packages/skopt/optimizer/gp.py", line 228, in gp_minimize\n    callback=callback, n_jobs=n_jobs)\n', '  File "/home/delano/working/fantasy/venv/lib/python3.6/site-packages/skopt/optimizer/base.py", line 248, in base_minimize\n    next_y = func(next_x)\n', '  File "/home/delano/working/fantasy/fantasy_py/util/hyper_param_tuning.py", line 869, in skopt_func\n    self.errors[flattened_hp_dict] = (ex, traceback.format_stack())\n']
----------------------------------------


{'activation': 'relu', 'dropout': 0.6415570251, 'hist_agg': 'none', 'layers': 3, 'learning_method': 'rmsprop', 'lr': 0.0063740374, 'n_cases': 24271, 'n_features': 324, 'n_games': 5, 'steps': 700, 'units': 65}
(sqlite3.OperationalError) unable to open database file (Background on this error at: http://sqlalche.me/e/e3q8)
['  File "scripts/meval.sc", line 3, in <module>\n    do_meval.process_cmd_line()\n', '  File "/home/delano/working/python_misc/ledona/__init__.py", line 19, in wrapper\n    result = timed_func(*args, **kwargs)\n', '  File "/home/delano/working/fantasy/fantasy_py/calculation/regression/exe/do_meval.py", line 562, in process_cmd_line\n    result = calc_engine.run_evaluation(eval_func)\n', '  File "/home/delano/working/fantasy/fantasy_py/calculation/engine.py", line 776, in run_evaluation\n    calc_def_id=calc_def_id)\n', '  File "/home/delano/working/fantasy/fantasy_py/calculation/engine.py", line 756, in calculate\n    **extra_kwargs)\n', '  File "/home/delano/working/fantasy/fantasy_py/calculation/regression/exe/do_meval.py", line 470, in eval_func\n    \'db\': meta_info.db_path.split(os.sep)[-1]})\n', '  File "/home/delano/working/fantasy/fantasy_py/util/hyper_param_tuning.py", line 893, in search\n    n_calls=self._iterations, n_random_starts=self._bayes_init_pts)\n', '  File "/home/delano/working/fantasy/venv/lib/python3.6/site-packages/skopt/optimizer/gp.py", line 228, in gp_minimize\n    callback=callback, n_jobs=n_jobs)\n', '  File "/home/delano/working/fantasy/venv/lib/python3.6/site-packages/skopt/optimizer/base.py", line 248, in base_minimize\n    next_y = func(next_x)\n', '  File "/home/delano/working/fantasy/fantasy_py/util/hyper_param_tuning.py", line 869, in skopt_func\n    self.errors[flattened_hp_dict] = (ex, traceback.format_stack())\n']
----------------------------------------


{'activation': 'relu', 'dropout': 0.6012054315, 'hist_agg': 'none', 'layers': 3, 'learning_method': 'rmsprop', 'lr': 0.0064369787, 'n_cases': 24174, 'n_features': 260, 'n_games': 4, 'steps': 700, 'units': 52}
(sqlite3.OperationalError) unable to open database file (Background on this error at: http://sqlalche.me/e/e3q8)
['  File "scripts/meval.sc", line 3, in <module>\n    do_meval.process_cmd_line()\n', '  File "/home/delano/working/python_misc/ledona/__init__.py", line 19, in wrapper\n    result = timed_func(*args, **kwargs)\n', '  File "/home/delano/working/fantasy/fantasy_py/calculation/regression/exe/do_meval.py", line 562, in process_cmd_line\n    result = calc_engine.run_evaluation(eval_func)\n', '  File "/home/delano/working/fantasy/fantasy_py/calculation/engine.py", line 776, in run_evaluation\n    calc_def_id=calc_def_id)\n', '  File "/home/delano/working/fantasy/fantasy_py/calculation/engine.py", line 756, in calculate\n    **extra_kwargs)\n', '  File "/home/delano/working/fantasy/fantasy_py/calculation/regression/exe/do_meval.py", line 470, in eval_func\n    \'db\': meta_info.db_path.split(os.sep)[-1]})\n', '  File "/home/delano/working/fantasy/fantasy_py/util/hyper_param_tuning.py", line 893, in search\n    n_calls=self._iterations, n_random_starts=self._bayes_init_pts)\n', '  File "/home/delano/working/fantasy/venv/lib/python3.6/site-packages/skopt/optimizer/gp.py", line 228, in gp_minimize\n    callback=callback, n_jobs=n_jobs)\n', '  File "/home/delano/working/fantasy/venv/lib/python3.6/site-packages/skopt/optimizer/base.py", line 248, in base_minimize\n    next_y = func(next_x)\n', '  File "/home/delano/working/fantasy/fantasy_py/util/hyper_param_tuning.py", line 869, in skopt_func\n    self.errors[flattened_hp_dict] = (ex, traceback.format_stack())\n']
----------------------------------------


{'activation': 'relu', 'dropout': 0.6420958127, 'hist_agg': 'none', 'layers': 4, 'learning_method': 'rmsprop', 'lr': 0.0071404885, 'n_cases': 24167, 'n_features': 260, 'n_games': 4, 'steps': 700, 'units': 35}
(sqlite3.OperationalError) unable to open database file (Background on this error at: http://sqlalche.me/e/e3q8)
['  File "scripts/meval.sc", line 3, in <module>\n    do_meval.process_cmd_line()\n', '  File "/home/delano/working/python_misc/ledona/__init__.py", line 19, in wrapper\n    result = timed_func(*args, **kwargs)\n', '  File "/home/delano/working/fantasy/fantasy_py/calculation/regression/exe/do_meval.py", line 562, in process_cmd_line\n    result = calc_engine.run_evaluation(eval_func)\n', '  File "/home/delano/working/fantasy/fantasy_py/calculation/engine.py", line 776, in run_evaluation\n    calc_def_id=calc_def_id)\n', '  File "/home/delano/working/fantasy/fantasy_py/calculation/engine.py", line 756, in calculate\n    **extra_kwargs)\n', '  File "/home/delano/working/fantasy/fantasy_py/calculation/regression/exe/do_meval.py", line 470, in eval_func\n    \'db\': meta_info.db_path.split(os.sep)[-1]})\n', '  File "/home/delano/working/fantasy/fantasy_py/util/hyper_param_tuning.py", line 893, in search\n    n_calls=self._iterations, n_random_starts=self._bayes_init_pts)\n', '  File "/home/delano/working/fantasy/venv/lib/python3.6/site-packages/skopt/optimizer/gp.py", line 228, in gp_minimize\n    callback=callback, n_jobs=n_jobs)\n', '  File "/home/delano/working/fantasy/venv/lib/python3.6/site-packages/skopt/optimizer/base.py", line 248, in base_minimize\n    next_y = func(next_x)\n', '  File "/home/delano/working/fantasy/fantasy_py/util/hyper_param_tuning.py", line 869, in skopt_func\n    self.errors[flattened_hp_dict] = (ex, traceback.format_stack())\n']
----------------------------------------


{'activation': 'relu', 'dropout': 0.6559066412, 'hist_agg': 'none', 'layers': 3, 'learning_method': 'rmsprop', 'lr': 0.0071369158, 'n_cases': 24151, 'n_features': 260, 'n_games': 4, 'steps': 700, 'units': 35}
(sqlite3.OperationalError) unable to open database file (Background on this error at: http://sqlalche.me/e/e3q8)
['  File "scripts/meval.sc", line 3, in <module>\n    do_meval.process_cmd_line()\n', '  File "/home/delano/working/python_misc/ledona/__init__.py", line 19, in wrapper\n    result = timed_func(*args, **kwargs)\n', '  File "/home/delano/working/fantasy/fantasy_py/calculation/regression/exe/do_meval.py", line 562, in process_cmd_line\n    result = calc_engine.run_evaluation(eval_func)\n', '  File "/home/delano/working/fantasy/fantasy_py/calculation/engine.py", line 776, in run_evaluation\n    calc_def_id=calc_def_id)\n', '  File "/home/delano/working/fantasy/fantasy_py/calculation/engine.py", line 756, in calculate\n    **extra_kwargs)\n', '  File "/home/delano/working/fantasy/fantasy_py/calculation/regression/exe/do_meval.py", line 470, in eval_func\n    \'db\': meta_info.db_path.split(os.sep)[-1]})\n', '  File "/home/delano/working/fantasy/fantasy_py/util/hyper_param_tuning.py", line 893, in search\n    n_calls=self._iterations, n_random_starts=self._bayes_init_pts)\n', '  File "/home/delano/working/fantasy/venv/lib/python3.6/site-packages/skopt/optimizer/gp.py", line 228, in gp_minimize\n    callback=callback, n_jobs=n_jobs)\n', '  File "/home/delano/working/fantasy/venv/lib/python3.6/site-packages/skopt/optimizer/base.py", line 248, in base_minimize\n    next_y = func(next_x)\n', '  File "/home/delano/working/fantasy/fantasy_py/util/hyper_param_tuning.py", line 869, in skopt_func\n    self.errors[flattened_hp_dict] = (ex, traceback.format_stack())\n']
----------------------------------------


{'activation': 'relu', 'dropout': 0.41152129, 'hist_agg': 'none', 'layers': 3, 'learning_method': 'rmsprop', 'lr': 0.0064199106, 'n_cases': 24160, 'n_features': 196, 'n_games': 3, 'steps': 700, 'units': 35}
(sqlite3.OperationalError) unable to open database file (Background on this error at: http://sqlalche.me/e/e3q8)
['  File "scripts/meval.sc", line 3, in <module>\n    do_meval.process_cmd_line()\n', '  File "/home/delano/working/python_misc/ledona/__init__.py", line 19, in wrapper\n    result = timed_func(*args, **kwargs)\n', '  File "/home/delano/working/fantasy/fantasy_py/calculation/regression/exe/do_meval.py", line 562, in process_cmd_line\n    result = calc_engine.run_evaluation(eval_func)\n', '  File "/home/delano/working/fantasy/fantasy_py/calculation/engine.py", line 776, in run_evaluation\n    calc_def_id=calc_def_id)\n', '  File "/home/delano/working/fantasy/fantasy_py/calculation/engine.py", line 756, in calculate\n    **extra_kwargs)\n', '  File "/home/delano/working/fantasy/fantasy_py/calculation/regression/exe/do_meval.py", line 470, in eval_func\n    \'db\': meta_info.db_path.split(os.sep)[-1]})\n', '  File "/home/delano/working/fantasy/fantasy_py/util/hyper_param_tuning.py", line 893, in search\n    n_calls=self._iterations, n_random_starts=self._bayes_init_pts)\n', '  File "/home/delano/working/fantasy/venv/lib/python3.6/site-packages/skopt/optimizer/gp.py", line 228, in gp_minimize\n    callback=callback, n_jobs=n_jobs)\n', '  File "/home/delano/working/fantasy/venv/lib/python3.6/site-packages/skopt/optimizer/base.py", line 248, in base_minimize\n    next_y = func(next_x)\n', '  File "/home/delano/working/fantasy/fantasy_py/util/hyper_param_tuning.py", line 869, in skopt_func\n    self.errors[flattened_hp_dict] = (ex, traceback.format_stack())\n']
----------------------------------------


{'activation': 'relu', 'dropout': 0.6862541687, 'hist_agg': 'none', 'layers': 3, 'learning_method': 'rmsprop', 'lr': 0.0060163804, 'n_cases': 9235, 'n_features': 260, 'n_games': 4, 'steps': 900, 'units': 30}
(sqlite3.OperationalError) unable to open database file (Background on this error at: http://sqlalche.me/e/e3q8)
['  File "scripts/meval.sc", line 3, in <module>\n    do_meval.process_cmd_line()\n', '  File "/home/delano/working/python_misc/ledona/__init__.py", line 19, in wrapper\n    result = timed_func(*args, **kwargs)\n', '  File "/home/delano/working/fantasy/fantasy_py/calculation/regression/exe/do_meval.py", line 562, in process_cmd_line\n    result = calc_engine.run_evaluation(eval_func)\n', '  File "/home/delano/working/fantasy/fantasy_py/calculation/engine.py", line 776, in run_evaluation\n    calc_def_id=calc_def_id)\n', '  File "/home/delano/working/fantasy/fantasy_py/calculation/engine.py", line 756, in calculate\n    **extra_kwargs)\n', '  File "/home/delano/working/fantasy/fantasy_py/calculation/regression/exe/do_meval.py", line 470, in eval_func\n    \'db\': meta_info.db_path.split(os.sep)[-1]})\n', '  File "/home/delano/working/fantasy/fantasy_py/util/hyper_param_tuning.py", line 893, in search\n    n_calls=self._iterations, n_random_starts=self._bayes_init_pts)\n', '  File "/home/delano/working/fantasy/venv/lib/python3.6/site-packages/skopt/optimizer/gp.py", line 228, in gp_minimize\n    callback=callback, n_jobs=n_jobs)\n', '  File "/home/delano/working/fantasy/venv/lib/python3.6/site-packages/skopt/optimizer/base.py", line 248, in base_minimize\n    next_y = func(next_x)\n', '  File "/home/delano/working/fantasy/fantasy_py/util/hyper_param_tuning.py", line 869, in skopt_func\n    self.errors[flattened_hp_dict] = (ex, traceback.format_stack())\n']
----------------------------------------


{'activation': 'relu', 'dropout': 0.6141172399, 'hist_agg': 'none', 'layers': 3, 'learning_method': 'rmsprop', 'lr': 0.0064159375, 'n_cases': 24145, 'n_features': 260, 'n_games': 4, 'steps': 700, 'units': 35}
(sqlite3.OperationalError) unable to open database file (Background on this error at: http://sqlalche.me/e/e3q8)
['  File "scripts/meval.sc", line 3, in <module>\n    do_meval.process_cmd_line()\n', '  File "/home/delano/working/python_misc/ledona/__init__.py", line 19, in wrapper\n    result = timed_func(*args, **kwargs)\n', '  File "/home/delano/working/fantasy/fantasy_py/calculation/regression/exe/do_meval.py", line 562, in process_cmd_line\n    result = calc_engine.run_evaluation(eval_func)\n', '  File "/home/delano/working/fantasy/fantasy_py/calculation/engine.py", line 776, in run_evaluation\n    calc_def_id=calc_def_id)\n', '  File "/home/delano/working/fantasy/fantasy_py/calculation/engine.py", line 756, in calculate\n    **extra_kwargs)\n', '  File "/home/delano/working/fantasy/fantasy_py/calculation/regression/exe/do_meval.py", line 470, in eval_func\n    \'db\': meta_info.db_path.split(os.sep)[-1]})\n', '  File "/home/delano/working/fantasy/fantasy_py/util/hyper_param_tuning.py", line 893, in search\n    n_calls=self._iterations, n_random_starts=self._bayes_init_pts)\n', '  File "/home/delano/working/fantasy/venv/lib/python3.6/site-packages/skopt/optimizer/gp.py", line 228, in gp_minimize\n    callback=callback, n_jobs=n_jobs)\n', '  File "/home/delano/working/fantasy/venv/lib/python3.6/site-packages/skopt/optimizer/base.py", line 248, in base_minimize\n    next_y = func(next_x)\n', '  File "/home/delano/working/fantasy/fantasy_py/util/hyper_param_tuning.py", line 869, in skopt_func\n    self.errors[flattened_hp_dict] = (ex, traceback.format_stack())\n']
----------------------------------------


{'activation': 'relu', 'dropout': 0.6416612361, 'hist_agg': 'none', 'layers': 3, 'learning_method': 'rmsprop', 'lr': 0.0064250793, 'n_cases': 24175, 'n_features': 260, 'n_games': 4, 'steps': 700, 'units': 42}
(sqlite3.OperationalError) unable to open database file (Background on this error at: http://sqlalche.me/e/e3q8)
['  File "scripts/meval.sc", line 3, in <module>\n    do_meval.process_cmd_line()\n', '  File "/home/delano/working/python_misc/ledona/__init__.py", line 19, in wrapper\n    result = timed_func(*args, **kwargs)\n', '  File "/home/delano/working/fantasy/fantasy_py/calculation/regression/exe/do_meval.py", line 562, in process_cmd_line\n    result = calc_engine.run_evaluation(eval_func)\n', '  File "/home/delano/working/fantasy/fantasy_py/calculation/engine.py", line 776, in run_evaluation\n    calc_def_id=calc_def_id)\n', '  File "/home/delano/working/fantasy/fantasy_py/calculation/engine.py", line 756, in calculate\n    **extra_kwargs)\n', '  File "/home/delano/working/fantasy/fantasy_py/calculation/regression/exe/do_meval.py", line 470, in eval_func\n    \'db\': meta_info.db_path.split(os.sep)[-1]})\n', '  File "/home/delano/working/fantasy/fantasy_py/util/hyper_param_tuning.py", line 893, in search\n    n_calls=self._iterations, n_random_starts=self._bayes_init_pts)\n', '  File "/home/delano/working/fantasy/venv/lib/python3.6/site-packages/skopt/optimizer/gp.py", line 228, in gp_minimize\n    callback=callback, n_jobs=n_jobs)\n', '  File "/home/delano/working/fantasy/venv/lib/python3.6/site-packages/skopt/optimizer/base.py", line 248, in base_minimize\n    next_y = func(next_x)\n', '  File "/home/delano/working/fantasy/fantasy_py/util/hyper_param_tuning.py", line 869, in skopt_func\n    self.errors[flattened_hp_dict] = (ex, traceback.format_stack())\n']
----------------------------------------


{'activation': 'relu', 'dropout': 0.6410620947, 'hist_agg': 'none', 'layers': 3, 'learning_method': 'rmsprop', 'lr': 0.0064309006, 'n_cases': 24199, 'n_features': 260, 'n_games': 4, 'steps': 700, 'units': 35}
(sqlite3.OperationalError) unable to open database file (Background on this error at: http://sqlalche.me/e/e3q8)
['  File "scripts/meval.sc", line 3, in <module>\n    do_meval.process_cmd_line()\n', '  File "/home/delano/working/python_misc/ledona/__init__.py", line 19, in wrapper\n    result = timed_func(*args, **kwargs)\n', '  File "/home/delano/working/fantasy/fantasy_py/calculation/regression/exe/do_meval.py", line 562, in process_cmd_line\n    result = calc_engine.run_evaluation(eval_func)\n', '  File "/home/delano/working/fantasy/fantasy_py/calculation/engine.py", line 776, in run_evaluation\n    calc_def_id=calc_def_id)\n', '  File "/home/delano/working/fantasy/fantasy_py/calculation/engine.py", line 756, in calculate\n    **extra_kwargs)\n', '  File "/home/delano/working/fantasy/fantasy_py/calculation/regression/exe/do_meval.py", line 470, in eval_func\n    \'db\': meta_info.db_path.split(os.sep)[-1]})\n', '  File "/home/delano/working/fantasy/fantasy_py/util/hyper_param_tuning.py", line 893, in search\n    n_calls=self._iterations, n_random_starts=self._bayes_init_pts)\n', '  File "/home/delano/working/fantasy/venv/lib/python3.6/site-packages/skopt/optimizer/gp.py", line 228, in gp_minimize\n    callback=callback, n_jobs=n_jobs)\n', '  File "/home/delano/working/fantasy/venv/lib/python3.6/site-packages/skopt/optimizer/base.py", line 248, in base_minimize\n    next_y = func(next_x)\n', '  File "/home/delano/working/fantasy/fantasy_py/util/hyper_param_tuning.py", line 869, in skopt_func\n    self.errors[flattened_hp_dict] = (ex, traceback.format_stack())\n']
----------------------------------------


{'activation': 'relu', 'dropout': 0.6411668542, 'hist_agg': 'none', 'layers': 3, 'learning_method': 'rmsprop', 'lr': 0.0064296559, 'n_cases': 24192, 'n_features': 260, 'n_games': 4, 'steps': 700, 'units': 35}
(sqlite3.OperationalError) unable to open database file (Background on this error at: http://sqlalche.me/e/e3q8)
['  File "scripts/meval.sc", line 3, in <module>\n    do_meval.process_cmd_line()\n', '  File "/home/delano/working/python_misc/ledona/__init__.py", line 19, in wrapper\n    result = timed_func(*args, **kwargs)\n', '  File "/home/delano/working/fantasy/fantasy_py/calculation/regression/exe/do_meval.py", line 562, in process_cmd_line\n    result = calc_engine.run_evaluation(eval_func)\n', '  File "/home/delano/working/fantasy/fantasy_py/calculation/engine.py", line 776, in run_evaluation\n    calc_def_id=calc_def_id)\n', '  File "/home/delano/working/fantasy/fantasy_py/calculation/engine.py", line 756, in calculate\n    **extra_kwargs)\n', '  File "/home/delano/working/fantasy/fantasy_py/calculation/regression/exe/do_meval.py", line 470, in eval_func\n    \'db\': meta_info.db_path.split(os.sep)[-1]})\n', '  File "/home/delano/working/fantasy/fantasy_py/util/hyper_param_tuning.py", line 893, in search\n    n_calls=self._iterations, n_random_starts=self._bayes_init_pts)\n', '  File "/home/delano/working/fantasy/venv/lib/python3.6/site-packages/skopt/optimizer/gp.py", line 228, in gp_minimize\n    callback=callback, n_jobs=n_jobs)\n', '  File "/home/delano/working/fantasy/venv/lib/python3.6/site-packages/skopt/optimizer/base.py", line 248, in base_minimize\n    next_y = func(next_x)\n', '  File "/home/delano/working/fantasy/fantasy_py/util/hyper_param_tuning.py", line 869, in skopt_func\n    self.errors[flattened_hp_dict] = (ex, traceback.format_stack())\n']
----------------------------------------


{'activation': 'relu', 'dropout': 0.6582402705, 'hist_agg': 'none', 'layers': 3, 'learning_method': 'rmsprop', 'lr': 0.0062328876, 'n_cases': 23209, 'n_features': 260, 'n_games': 4, 'steps': 800, 'units': 33}
(sqlite3.OperationalError) unable to open database file (Background on this error at: http://sqlalche.me/e/e3q8)
['  File "scripts/meval.sc", line 3, in <module>\n    do_meval.process_cmd_line()\n', '  File "/home/delano/working/python_misc/ledona/__init__.py", line 19, in wrapper\n    result = timed_func(*args, **kwargs)\n', '  File "/home/delano/working/fantasy/fantasy_py/calculation/regression/exe/do_meval.py", line 562, in process_cmd_line\n    result = calc_engine.run_evaluation(eval_func)\n', '  File "/home/delano/working/fantasy/fantasy_py/calculation/engine.py", line 776, in run_evaluation\n    calc_def_id=calc_def_id)\n', '  File "/home/delano/working/fantasy/fantasy_py/calculation/engine.py", line 756, in calculate\n    **extra_kwargs)\n', '  File "/home/delano/working/fantasy/fantasy_py/calculation/regression/exe/do_meval.py", line 470, in eval_func\n    \'db\': meta_info.db_path.split(os.sep)[-1]})\n', '  File "/home/delano/working/fantasy/fantasy_py/util/hyper_param_tuning.py", line 893, in search\n    n_calls=self._iterations, n_random_starts=self._bayes_init_pts)\n', '  File "/home/delano/working/fantasy/venv/lib/python3.6/site-packages/skopt/optimizer/gp.py", line 228, in gp_minimize\n    callback=callback, n_jobs=n_jobs)\n', '  File "/home/delano/working/fantasy/venv/lib/python3.6/site-packages/skopt/optimizer/base.py", line 248, in base_minimize\n    next_y = func(next_x)\n', '  File "/home/delano/working/fantasy/fantasy_py/util/hyper_param_tuning.py", line 869, in skopt_func\n    self.errors[flattened_hp_dict] = (ex, traceback.format_stack())\n']
----------------------------------------


{'activation': 'relu', 'dropout': 0.641392129, 'hist_agg': 'none', 'layers': 3, 'learning_method': 'rmsprop', 'lr': 0.006427128, 'n_cases': 24180, 'n_features': 260, 'n_games': 4, 'steps': 700, 'units': 35}
(sqlite3.OperationalError) unable to open database file (Background on this error at: http://sqlalche.me/e/e3q8)
['  File "scripts/meval.sc", line 3, in <module>\n    do_meval.process_cmd_line()\n', '  File "/home/delano/working/python_misc/ledona/__init__.py", line 19, in wrapper\n    result = timed_func(*args, **kwargs)\n', '  File "/home/delano/working/fantasy/fantasy_py/calculation/regression/exe/do_meval.py", line 562, in process_cmd_line\n    result = calc_engine.run_evaluation(eval_func)\n', '  File "/home/delano/working/fantasy/fantasy_py/calculation/engine.py", line 776, in run_evaluation\n    calc_def_id=calc_def_id)\n', '  File "/home/delano/working/fantasy/fantasy_py/calculation/engine.py", line 756, in calculate\n    **extra_kwargs)\n', '  File "/home/delano/working/fantasy/fantasy_py/calculation/regression/exe/do_meval.py", line 470, in eval_func\n    \'db\': meta_info.db_path.split(os.sep)[-1]})\n', '  File "/home/delano/working/fantasy/fantasy_py/util/hyper_param_tuning.py", line 893, in search\n    n_calls=self._iterations, n_random_starts=self._bayes_init_pts)\n', '  File "/home/delano/working/fantasy/venv/lib/python3.6/site-packages/skopt/optimizer/gp.py", line 228, in gp_minimize\n    callback=callback, n_jobs=n_jobs)\n', '  File "/home/delano/working/fantasy/venv/lib/python3.6/site-packages/skopt/optimizer/base.py", line 248, in base_minimize\n    next_y = func(next_x)\n', '  File "/home/delano/working/fantasy/fantasy_py/util/hyper_param_tuning.py", line 869, in skopt_func\n    self.errors[flattened_hp_dict] = (ex, traceback.format_stack())\n']
----------------------------------------


{'activation': 'relu', 'dropout': 0.6094982376, 'hist_agg': 'none', 'layers': 2, 'learning_method': 'rmsprop', 'lr': 0.0088514611, 'n_cases': 28289, 'n_features': 132, 'n_games': 2, 'steps': 700, 'units': 55}
(sqlite3.OperationalError) unable to open database file (Background on this error at: http://sqlalche.me/e/e3q8)
['  File "scripts/meval.sc", line 3, in <module>\n    do_meval.process_cmd_line()\n', '  File "/home/delano/working/python_misc/ledona/__init__.py", line 19, in wrapper\n    result = timed_func(*args, **kwargs)\n', '  File "/home/delano/working/fantasy/fantasy_py/calculation/regression/exe/do_meval.py", line 562, in process_cmd_line\n    result = calc_engine.run_evaluation(eval_func)\n', '  File "/home/delano/working/fantasy/fantasy_py/calculation/engine.py", line 776, in run_evaluation\n    calc_def_id=calc_def_id)\n', '  File "/home/delano/working/fantasy/fantasy_py/calculation/engine.py", line 756, in calculate\n    **extra_kwargs)\n', '  File "/home/delano/working/fantasy/fantasy_py/calculation/regression/exe/do_meval.py", line 470, in eval_func\n    \'db\': meta_info.db_path.split(os.sep)[-1]})\n', '  File "/home/delano/working/fantasy/fantasy_py/util/hyper_param_tuning.py", line 893, in search\n    n_calls=self._iterations, n_random_starts=self._bayes_init_pts)\n', '  File "/home/delano/working/fantasy/venv/lib/python3.6/site-packages/skopt/optimizer/gp.py", line 228, in gp_minimize\n    callback=callback, n_jobs=n_jobs)\n', '  File "/home/delano/working/fantasy/venv/lib/python3.6/site-packages/skopt/optimizer/base.py", line 248, in base_minimize\n    next_y = func(next_x)\n', '  File "/home/delano/working/fantasy/fantasy_py/util/hyper_param_tuning.py", line 869, in skopt_func\n    self.errors[flattened_hp_dict] = (ex, traceback.format_stack())\n']
----------------------------------------


{'activation': 'tanh', 'dropout': 0.4046764629, 'hist_agg': 'none', 'layers': 4, 'learning_method': 'sgd', 'lr': 0.0067241934, 'n_cases': 22550, 'n_features': 324, 'n_games': 5, 'steps': 700, 'units': 60}
(sqlite3.OperationalError) unable to open database file (Background on this error at: http://sqlalche.me/e/e3q8)
['  File "scripts/meval.sc", line 3, in <module>\n    do_meval.process_cmd_line()\n', '  File "/home/delano/working/python_misc/ledona/__init__.py", line 19, in wrapper\n    result = timed_func(*args, **kwargs)\n', '  File "/home/delano/working/fantasy/fantasy_py/calculation/regression/exe/do_meval.py", line 562, in process_cmd_line\n    result = calc_engine.run_evaluation(eval_func)\n', '  File "/home/delano/working/fantasy/fantasy_py/calculation/engine.py", line 776, in run_evaluation\n    calc_def_id=calc_def_id)\n', '  File "/home/delano/working/fantasy/fantasy_py/calculation/engine.py", line 756, in calculate\n    **extra_kwargs)\n', '  File "/home/delano/working/fantasy/fantasy_py/calculation/regression/exe/do_meval.py", line 470, in eval_func\n    \'db\': meta_info.db_path.split(os.sep)[-1]})\n', '  File "/home/delano/working/fantasy/fantasy_py/util/hyper_param_tuning.py", line 893, in search\n    n_calls=self._iterations, n_random_starts=self._bayes_init_pts)\n', '  File "/home/delano/working/fantasy/venv/lib/python3.6/site-packages/skopt/optimizer/gp.py", line 228, in gp_minimize\n    callback=callback, n_jobs=n_jobs)\n', '  File "/home/delano/working/fantasy/venv/lib/python3.6/site-packages/skopt/optimizer/base.py", line 248, in base_minimize\n    next_y = func(next_x)\n', '  File "/home/delano/working/fantasy/fantasy_py/util/hyper_param_tuning.py", line 869, in skopt_func\n    self.errors[flattened_hp_dict] = (ex, traceback.format_stack())\n']
----------------------------------------


{'activation': 'relu', 'dropout': 0.6417485412, 'hist_agg': 'none', 'layers': 3, 'learning_method': 'rmsprop', 'lr': 0.0064232382, 'n_cases': 24163, 'n_features': 260, 'n_games': 4, 'steps': 700, 'units': 35}
(sqlite3.OperationalError) unable to open database file (Background on this error at: http://sqlalche.me/e/e3q8)
['  File "scripts/meval.sc", line 3, in <module>\n    do_meval.process_cmd_line()\n', '  File "/home/delano/working/python_misc/ledona/__init__.py", line 19, in wrapper\n    result = timed_func(*args, **kwargs)\n', '  File "/home/delano/working/fantasy/fantasy_py/calculation/regression/exe/do_meval.py", line 562, in process_cmd_line\n    result = calc_engine.run_evaluation(eval_func)\n', '  File "/home/delano/working/fantasy/fantasy_py/calculation/engine.py", line 776, in run_evaluation\n    calc_def_id=calc_def_id)\n', '  File "/home/delano/working/fantasy/fantasy_py/calculation/engine.py", line 756, in calculate\n    **extra_kwargs)\n', '  File "/home/delano/working/fantasy/fantasy_py/calculation/regression/exe/do_meval.py", line 470, in eval_func\n    \'db\': meta_info.db_path.split(os.sep)[-1]})\n', '  File "/home/delano/working/fantasy/fantasy_py/util/hyper_param_tuning.py", line 893, in search\n    n_calls=self._iterations, n_random_starts=self._bayes_init_pts)\n', '  File "/home/delano/working/fantasy/venv/lib/python3.6/site-packages/skopt/optimizer/gp.py", line 228, in gp_minimize\n    callback=callback, n_jobs=n_jobs)\n', '  File "/home/delano/working/fantasy/venv/lib/python3.6/site-packages/skopt/optimizer/base.py", line 248, in base_minimize\n    next_y = func(next_x)\n', '  File "/home/delano/working/fantasy/fantasy_py/util/hyper_param_tuning.py", line 869, in skopt_func\n    self.errors[flattened_hp_dict] = (ex, traceback.format_stack())\n']
----------------------------------------


{'activation': 'relu', 'dropout': 0.642412802, 'hist_agg': 'none', 'layers': 3, 'learning_method': 'rmsprop', 'lr': 0.0064157443, 'n_cases': 24131, 'n_features': 260, 'n_games': 4, 'steps': 700, 'units': 35}
(sqlite3.OperationalError) unable to open database file (Background on this error at: http://sqlalche.me/e/e3q8)
['  File "scripts/meval.sc", line 3, in <module>\n    do_meval.process_cmd_line()\n', '  File "/home/delano/working/python_misc/ledona/__init__.py", line 19, in wrapper\n    result = timed_func(*args, **kwargs)\n', '  File "/home/delano/working/fantasy/fantasy_py/calculation/regression/exe/do_meval.py", line 562, in process_cmd_line\n    result = calc_engine.run_evaluation(eval_func)\n', '  File "/home/delano/working/fantasy/fantasy_py/calculation/engine.py", line 776, in run_evaluation\n    calc_def_id=calc_def_id)\n', '  File "/home/delano/working/fantasy/fantasy_py/calculation/engine.py", line 756, in calculate\n    **extra_kwargs)\n', '  File "/home/delano/working/fantasy/fantasy_py/calculation/regression/exe/do_meval.py", line 470, in eval_func\n    \'db\': meta_info.db_path.split(os.sep)[-1]})\n', '  File "/home/delano/working/fantasy/fantasy_py/util/hyper_param_tuning.py", line 893, in search\n    n_calls=self._iterations, n_random_starts=self._bayes_init_pts)\n', '  File "/home/delano/working/fantasy/venv/lib/python3.6/site-packages/skopt/optimizer/gp.py", line 228, in gp_minimize\n    callback=callback, n_jobs=n_jobs)\n', '  File "/home/delano/working/fantasy/venv/lib/python3.6/site-packages/skopt/optimizer/base.py", line 248, in base_minimize\n    next_y = func(next_x)\n', '  File "/home/delano/working/fantasy/fantasy_py/util/hyper_param_tuning.py", line 869, in skopt_func\n    self.errors[flattened_hp_dict] = (ex, traceback.format_stack())\n']
----------------------------------------


{'activation': 'relu', 'dropout': 0.6382727864, 'hist_agg': 'none', 'layers': 3, 'learning_method': 'rmsprop', 'lr': 0.0095794712, 'n_cases': 30683, 'n_features': 196, 'n_games': 3, 'steps': 800, 'units': 35}
(sqlite3.OperationalError) unable to open database file (Background on this error at: http://sqlalche.me/e/e3q8)
['  File "scripts/meval.sc", line 3, in <module>\n    do_meval.process_cmd_line()\n', '  File "/home/delano/working/python_misc/ledona/__init__.py", line 19, in wrapper\n    result = timed_func(*args, **kwargs)\n', '  File "/home/delano/working/fantasy/fantasy_py/calculation/regression/exe/do_meval.py", line 562, in process_cmd_line\n    result = calc_engine.run_evaluation(eval_func)\n', '  File "/home/delano/working/fantasy/fantasy_py/calculation/engine.py", line 776, in run_evaluation\n    calc_def_id=calc_def_id)\n', '  File "/home/delano/working/fantasy/fantasy_py/calculation/engine.py", line 756, in calculate\n    **extra_kwargs)\n', '  File "/home/delano/working/fantasy/fantasy_py/calculation/regression/exe/do_meval.py", line 470, in eval_func\n    \'db\': meta_info.db_path.split(os.sep)[-1]})\n', '  File "/home/delano/working/fantasy/fantasy_py/util/hyper_param_tuning.py", line 893, in search\n    n_calls=self._iterations, n_random_starts=self._bayes_init_pts)\n', '  File "/home/delano/working/fantasy/venv/lib/python3.6/site-packages/skopt/optimizer/gp.py", line 228, in gp_minimize\n    callback=callback, n_jobs=n_jobs)\n', '  File "/home/delano/working/fantasy/venv/lib/python3.6/site-packages/skopt/optimizer/base.py", line 248, in base_minimize\n    next_y = func(next_x)\n', '  File "/home/delano/working/fantasy/fantasy_py/util/hyper_param_tuning.py", line 869, in skopt_func\n    self.errors[flattened_hp_dict] = (ex, traceback.format_stack())\n']
----------------------------------------


{'activation': 'relu', 'dropout': 0.6417889583, 'hist_agg': 'none', 'layers': 3, 'learning_method': 'rmsprop', 'lr': 0.0064225062, 'n_cases': 24156, 'n_features': 260, 'n_games': 4, 'steps': 700, 'units': 35}
(sqlite3.OperationalError) unable to open database file (Background on this error at: http://sqlalche.me/e/e3q8)
['  File "scripts/meval.sc", line 3, in <module>\n    do_meval.process_cmd_line()\n', '  File "/home/delano/working/python_misc/ledona/__init__.py", line 19, in wrapper\n    result = timed_func(*args, **kwargs)\n', '  File "/home/delano/working/fantasy/fantasy_py/calculation/regression/exe/do_meval.py", line 562, in process_cmd_line\n    result = calc_engine.run_evaluation(eval_func)\n', '  File "/home/delano/working/fantasy/fantasy_py/calculation/engine.py", line 776, in run_evaluation\n    calc_def_id=calc_def_id)\n', '  File "/home/delano/working/fantasy/fantasy_py/calculation/engine.py", line 756, in calculate\n    **extra_kwargs)\n', '  File "/home/delano/working/fantasy/fantasy_py/calculation/regression/exe/do_meval.py", line 470, in eval_func\n    \'db\': meta_info.db_path.split(os.sep)[-1]})\n', '  File "/home/delano/working/fantasy/fantasy_py/util/hyper_param_tuning.py", line 893, in search\n    n_calls=self._iterations, n_random_starts=self._bayes_init_pts)\n', '  File "/home/delano/working/fantasy/venv/lib/python3.6/site-packages/skopt/optimizer/gp.py", line 228, in gp_minimize\n    callback=callback, n_jobs=n_jobs)\n', '  File "/home/delano/working/fantasy/venv/lib/python3.6/site-packages/skopt/optimizer/base.py", line 248, in base_minimize\n    next_y = func(next_x)\n', '  File "/home/delano/working/fantasy/fantasy_py/util/hyper_param_tuning.py", line 869, in skopt_func\n    self.errors[flattened_hp_dict] = (ex, traceback.format_stack())\n']
----------------------------------------


{'activation': 'relu', 'dropout': 0.6432762973, 'hist_agg': 'none', 'layers': 3, 'learning_method': 'rmsprop', 'lr': 0.0064054605, 'n_cases': 24084, 'n_features': 260, 'n_games': 4, 'steps': 700, 'units': 35}
(sqlite3.OperationalError) unable to open database file (Background on this error at: http://sqlalche.me/e/e3q8)
['  File "scripts/meval.sc", line 3, in <module>\n    do_meval.process_cmd_line()\n', '  File "/home/delano/working/python_misc/ledona/__init__.py", line 19, in wrapper\n    result = timed_func(*args, **kwargs)\n', '  File "/home/delano/working/fantasy/fantasy_py/calculation/regression/exe/do_meval.py", line 562, in process_cmd_line\n    result = calc_engine.run_evaluation(eval_func)\n', '  File "/home/delano/working/fantasy/fantasy_py/calculation/engine.py", line 776, in run_evaluation\n    calc_def_id=calc_def_id)\n', '  File "/home/delano/working/fantasy/fantasy_py/calculation/engine.py", line 756, in calculate\n    **extra_kwargs)\n', '  File "/home/delano/working/fantasy/fantasy_py/calculation/regression/exe/do_meval.py", line 470, in eval_func\n    \'db\': meta_info.db_path.split(os.sep)[-1]})\n', '  File "/home/delano/working/fantasy/fantasy_py/util/hyper_param_tuning.py", line 893, in search\n    n_calls=self._iterations, n_random_starts=self._bayes_init_pts)\n', '  File "/home/delano/working/fantasy/venv/lib/python3.6/site-packages/skopt/optimizer/gp.py", line 228, in gp_minimize\n    callback=callback, n_jobs=n_jobs)\n', '  File "/home/delano/working/fantasy/venv/lib/python3.6/site-packages/skopt/optimizer/base.py", line 248, in base_minimize\n    next_y = func(next_x)\n', '  File "/home/delano/working/fantasy/fantasy_py/util/hyper_param_tuning.py", line 869, in skopt_func\n    self.errors[flattened_hp_dict] = (ex, traceback.format_stack())\n']
----------------------------------------


{'activation': 'tanh', 'dropout': 0.4377748683, 'hist_agg': 'none', 'layers': 4, 'learning_method': 'rmsprop', 'lr': 0.0053377004, 'n_cases': 10288, 'n_features': 132, 'n_games': 2, 'steps': 800, 'units': 78}
(sqlite3.OperationalError) unable to open database file (Background on this error at: http://sqlalche.me/e/e3q8)
['  File "scripts/meval.sc", line 3, in <module>\n    do_meval.process_cmd_line()\n', '  File "/home/delano/working/python_misc/ledona/__init__.py", line 19, in wrapper\n    result = timed_func(*args, **kwargs)\n', '  File "/home/delano/working/fantasy/fantasy_py/calculation/regression/exe/do_meval.py", line 562, in process_cmd_line\n    result = calc_engine.run_evaluation(eval_func)\n', '  File "/home/delano/working/fantasy/fantasy_py/calculation/engine.py", line 776, in run_evaluation\n    calc_def_id=calc_def_id)\n', '  File "/home/delano/working/fantasy/fantasy_py/calculation/engine.py", line 756, in calculate\n    **extra_kwargs)\n', '  File "/home/delano/working/fantasy/fantasy_py/calculation/regression/exe/do_meval.py", line 470, in eval_func\n    \'db\': meta_info.db_path.split(os.sep)[-1]})\n', '  File "/home/delano/working/fantasy/fantasy_py/util/hyper_param_tuning.py", line 893, in search\n    n_calls=self._iterations, n_random_starts=self._bayes_init_pts)\n', '  File "/home/delano/working/fantasy/venv/lib/python3.6/site-packages/skopt/optimizer/gp.py", line 228, in gp_minimize\n    callback=callback, n_jobs=n_jobs)\n', '  File "/home/delano/working/fantasy/venv/lib/python3.6/site-packages/skopt/optimizer/base.py", line 248, in base_minimize\n    next_y = func(next_x)\n', '  File "/home/delano/working/fantasy/fantasy_py/util/hyper_param_tuning.py", line 869, in skopt_func\n    self.errors[flattened_hp_dict] = (ex, traceback.format_stack())\n']
----------------------------------------


{'activation': 'relu', 'dropout': 0.4710160507, 'hist_agg': 'none', 'layers': 2, 'learning_method': 'sgd', 'lr': 0.0098971703, 'n_cases': 19087, 'n_features': 196, 'n_games': 3, 'steps': 600, 'units': 76}
(sqlite3.OperationalError) unable to open database file (Background on this error at: http://sqlalche.me/e/e3q8)
['  File "scripts/meval.sc", line 3, in <module>\n    do_meval.process_cmd_line()\n', '  File "/home/delano/working/python_misc/ledona/__init__.py", line 19, in wrapper\n    result = timed_func(*args, **kwargs)\n', '  File "/home/delano/working/fantasy/fantasy_py/calculation/regression/exe/do_meval.py", line 562, in process_cmd_line\n    result = calc_engine.run_evaluation(eval_func)\n', '  File "/home/delano/working/fantasy/fantasy_py/calculation/engine.py", line 776, in run_evaluation\n    calc_def_id=calc_def_id)\n', '  File "/home/delano/working/fantasy/fantasy_py/calculation/engine.py", line 756, in calculate\n    **extra_kwargs)\n', '  File "/home/delano/working/fantasy/fantasy_py/calculation/regression/exe/do_meval.py", line 470, in eval_func\n    \'db\': meta_info.db_path.split(os.sep)[-1]})\n', '  File "/home/delano/working/fantasy/fantasy_py/util/hyper_param_tuning.py", line 893, in search\n    n_calls=self._iterations, n_random_starts=self._bayes_init_pts)\n', '  File "/home/delano/working/fantasy/venv/lib/python3.6/site-packages/skopt/optimizer/gp.py", line 228, in gp_minimize\n    callback=callback, n_jobs=n_jobs)\n', '  File "/home/delano/working/fantasy/venv/lib/python3.6/site-packages/skopt/optimizer/base.py", line 248, in base_minimize\n    next_y = func(next_x)\n', '  File "/home/delano/working/fantasy/fantasy_py/util/hyper_param_tuning.py", line 869, in skopt_func\n    self.errors[flattened_hp_dict] = (ex, traceback.format_stack())\n']
----------------------------------------


