{'activation': 'relu', 'dropout': 0.7, 'hist_agg': 'none', 'layers': 5, 'learning_method': 'adagrad', 'n_cases': 500, 'n_features': 68, 'n_games': 1, 'steps': 1000, 'units': 20}
(sqlite3.OperationalError) unable to open database file (Background on this error at: http://sqlalche.me/e/e3q8)
['  File "scripts/meval.sc", line 3, in <module>\n    do_meval.process_cmd_line()\n', '  File "/home/delano/working/python_misc/ledona/__init__.py", line 19, in wrapper\n    result = timed_func(*args, **kwargs)\n', '  File "/home/delano/working/fantasy/fantasy_py/calculation/regression/exe/do_meval.py", line 562, in process_cmd_line\n    result = calc_engine.run_evaluation(eval_func)\n', '  File "/home/delano/working/fantasy/fantasy_py/calculation/engine.py", line 776, in run_evaluation\n    calc_def_id=calc_def_id)\n', '  File "/home/delano/working/fantasy/fantasy_py/calculation/engine.py", line 756, in calculate\n    **extra_kwargs)\n', '  File "/home/delano/working/fantasy/fantasy_py/calculation/regression/exe/do_meval.py", line 470, in eval_func\n    \'db\': meta_info.db_path.split(os.sep)[-1]})\n', '  File "/home/delano/working/fantasy/fantasy_py/util/hyper_param_tuning.py", line 893, in search\n    n_calls=self._iterations, n_random_starts=self._bayes_init_pts)\n', '  File "/home/delano/working/fantasy/venv/lib/python3.6/site-packages/skopt/optimizer/gp.py", line 228, in gp_minimize\n    callback=callback, n_jobs=n_jobs)\n', '  File "/home/delano/working/fantasy/venv/lib/python3.6/site-packages/skopt/optimizer/base.py", line 248, in base_minimize\n    next_y = func(next_x)\n', '  File "/home/delano/working/fantasy/fantasy_py/util/hyper_param_tuning.py", line 869, in skopt_func\n    self.errors[flattened_hp_dict] = (ex, traceback.format_stack())\n']
----------------------------------------


{'activation': 'relu', 'dropout': 0.3084696854, 'hist_agg': 'none', 'layers': 3, 'learning_method': 'adagrad', 'n_cases': 40000, 'n_features': 68, 'n_games': 1, 'steps': 800, 'units': 21}
(sqlite3.OperationalError) unable to open database file (Background on this error at: http://sqlalche.me/e/e3q8)
['  File "scripts/meval.sc", line 3, in <module>\n    do_meval.process_cmd_line()\n', '  File "/home/delano/working/python_misc/ledona/__init__.py", line 19, in wrapper\n    result = timed_func(*args, **kwargs)\n', '  File "/home/delano/working/fantasy/fantasy_py/calculation/regression/exe/do_meval.py", line 562, in process_cmd_line\n    result = calc_engine.run_evaluation(eval_func)\n', '  File "/home/delano/working/fantasy/fantasy_py/calculation/engine.py", line 776, in run_evaluation\n    calc_def_id=calc_def_id)\n', '  File "/home/delano/working/fantasy/fantasy_py/calculation/engine.py", line 756, in calculate\n    **extra_kwargs)\n', '  File "/home/delano/working/fantasy/fantasy_py/calculation/regression/exe/do_meval.py", line 470, in eval_func\n    \'db\': meta_info.db_path.split(os.sep)[-1]})\n', '  File "/home/delano/working/fantasy/fantasy_py/util/hyper_param_tuning.py", line 893, in search\n    n_calls=self._iterations, n_random_starts=self._bayes_init_pts)\n', '  File "/home/delano/working/fantasy/venv/lib/python3.6/site-packages/skopt/optimizer/gp.py", line 228, in gp_minimize\n    callback=callback, n_jobs=n_jobs)\n', '  File "/home/delano/working/fantasy/venv/lib/python3.6/site-packages/skopt/optimizer/base.py", line 248, in base_minimize\n    next_y = func(next_x)\n', '  File "/home/delano/working/fantasy/fantasy_py/util/hyper_param_tuning.py", line 869, in skopt_func\n    self.errors[flattened_hp_dict] = (ex, traceback.format_stack())\n']
----------------------------------------


{'activation': 'sigmoid', 'dropout': 0.4555506922, 'hist_agg': 'none', 'layers': 5, 'learning_method': 'nadam', 'n_cases': 4320, 'n_features': 452, 'n_games': 7, 'steps': 100, 'units': 92}
(sqlite3.OperationalError) unable to open database file (Background on this error at: http://sqlalche.me/e/e3q8)
['  File "scripts/meval.sc", line 3, in <module>\n    do_meval.process_cmd_line()\n', '  File "/home/delano/working/python_misc/ledona/__init__.py", line 19, in wrapper\n    result = timed_func(*args, **kwargs)\n', '  File "/home/delano/working/fantasy/fantasy_py/calculation/regression/exe/do_meval.py", line 562, in process_cmd_line\n    result = calc_engine.run_evaluation(eval_func)\n', '  File "/home/delano/working/fantasy/fantasy_py/calculation/engine.py", line 776, in run_evaluation\n    calc_def_id=calc_def_id)\n', '  File "/home/delano/working/fantasy/fantasy_py/calculation/engine.py", line 756, in calculate\n    **extra_kwargs)\n', '  File "/home/delano/working/fantasy/fantasy_py/calculation/regression/exe/do_meval.py", line 470, in eval_func\n    \'db\': meta_info.db_path.split(os.sep)[-1]})\n', '  File "/home/delano/working/fantasy/fantasy_py/util/hyper_param_tuning.py", line 893, in search\n    n_calls=self._iterations, n_random_starts=self._bayes_init_pts)\n', '  File "/home/delano/working/fantasy/venv/lib/python3.6/site-packages/skopt/optimizer/gp.py", line 228, in gp_minimize\n    callback=callback, n_jobs=n_jobs)\n', '  File "/home/delano/working/fantasy/venv/lib/python3.6/site-packages/skopt/optimizer/base.py", line 248, in base_minimize\n    next_y = func(next_x)\n', '  File "/home/delano/working/fantasy/fantasy_py/util/hyper_param_tuning.py", line 869, in skopt_func\n    self.errors[flattened_hp_dict] = (ex, traceback.format_stack())\n']
----------------------------------------


{'activation': 'linear', 'dropout': 0.3002347696, 'hist_agg': 'none', 'layers': 5, 'learning_method': 'adagrad', 'n_cases': 25346, 'n_features': 68, 'n_games': 1, 'steps': 400, 'units': 20}
(sqlite3.OperationalError) unable to open database file (Background on this error at: http://sqlalche.me/e/e3q8)
['  File "scripts/meval.sc", line 3, in <module>\n    do_meval.process_cmd_line()\n', '  File "/home/delano/working/python_misc/ledona/__init__.py", line 19, in wrapper\n    result = timed_func(*args, **kwargs)\n', '  File "/home/delano/working/fantasy/fantasy_py/calculation/regression/exe/do_meval.py", line 562, in process_cmd_line\n    result = calc_engine.run_evaluation(eval_func)\n', '  File "/home/delano/working/fantasy/fantasy_py/calculation/engine.py", line 776, in run_evaluation\n    calc_def_id=calc_def_id)\n', '  File "/home/delano/working/fantasy/fantasy_py/calculation/engine.py", line 756, in calculate\n    **extra_kwargs)\n', '  File "/home/delano/working/fantasy/fantasy_py/calculation/regression/exe/do_meval.py", line 470, in eval_func\n    \'db\': meta_info.db_path.split(os.sep)[-1]})\n', '  File "/home/delano/working/fantasy/fantasy_py/util/hyper_param_tuning.py", line 893, in search\n    n_calls=self._iterations, n_random_starts=self._bayes_init_pts)\n', '  File "/home/delano/working/fantasy/venv/lib/python3.6/site-packages/skopt/optimizer/gp.py", line 228, in gp_minimize\n    callback=callback, n_jobs=n_jobs)\n', '  File "/home/delano/working/fantasy/venv/lib/python3.6/site-packages/skopt/optimizer/base.py", line 248, in base_minimize\n    next_y = func(next_x)\n', '  File "/home/delano/working/fantasy/fantasy_py/util/hyper_param_tuning.py", line 869, in skopt_func\n    self.errors[flattened_hp_dict] = (ex, traceback.format_stack())\n']
----------------------------------------


{'activation': 'relu', 'dropout': 0.3, 'hist_agg': 'none', 'layers': 5, 'learning_method': 'adagrad', 'n_cases': 521, 'n_features': 68, 'n_games': 1, 'steps': 1000, 'units': 100}
(sqlite3.OperationalError) unable to open database file (Background on this error at: http://sqlalche.me/e/e3q8)
['  File "scripts/meval.sc", line 3, in <module>\n    do_meval.process_cmd_line()\n', '  File "/home/delano/working/python_misc/ledona/__init__.py", line 19, in wrapper\n    result = timed_func(*args, **kwargs)\n', '  File "/home/delano/working/fantasy/fantasy_py/calculation/regression/exe/do_meval.py", line 562, in process_cmd_line\n    result = calc_engine.run_evaluation(eval_func)\n', '  File "/home/delano/working/fantasy/fantasy_py/calculation/engine.py", line 776, in run_evaluation\n    calc_def_id=calc_def_id)\n', '  File "/home/delano/working/fantasy/fantasy_py/calculation/engine.py", line 756, in calculate\n    **extra_kwargs)\n', '  File "/home/delano/working/fantasy/fantasy_py/calculation/regression/exe/do_meval.py", line 470, in eval_func\n    \'db\': meta_info.db_path.split(os.sep)[-1]})\n', '  File "/home/delano/working/fantasy/fantasy_py/util/hyper_param_tuning.py", line 893, in search\n    n_calls=self._iterations, n_random_starts=self._bayes_init_pts)\n', '  File "/home/delano/working/fantasy/venv/lib/python3.6/site-packages/skopt/optimizer/gp.py", line 228, in gp_minimize\n    callback=callback, n_jobs=n_jobs)\n', '  File "/home/delano/working/fantasy/venv/lib/python3.6/site-packages/skopt/optimizer/base.py", line 248, in base_minimize\n    next_y = func(next_x)\n', '  File "/home/delano/working/fantasy/fantasy_py/util/hyper_param_tuning.py", line 869, in skopt_func\n    self.errors[flattened_hp_dict] = (ex, traceback.format_stack())\n']
----------------------------------------


{'activation': 'linear', 'dropout': 0.6823052773, 'hist_agg': 'none', 'layers': 3, 'learning_method': 'nadam', 'n_cases': 10857, 'n_features': 388, 'n_games': 6, 'steps': 200, 'units': 63}
(sqlite3.OperationalError) unable to open database file (Background on this error at: http://sqlalche.me/e/e3q8)
['  File "scripts/meval.sc", line 3, in <module>\n    do_meval.process_cmd_line()\n', '  File "/home/delano/working/python_misc/ledona/__init__.py", line 19, in wrapper\n    result = timed_func(*args, **kwargs)\n', '  File "/home/delano/working/fantasy/fantasy_py/calculation/regression/exe/do_meval.py", line 562, in process_cmd_line\n    result = calc_engine.run_evaluation(eval_func)\n', '  File "/home/delano/working/fantasy/fantasy_py/calculation/engine.py", line 776, in run_evaluation\n    calc_def_id=calc_def_id)\n', '  File "/home/delano/working/fantasy/fantasy_py/calculation/engine.py", line 756, in calculate\n    **extra_kwargs)\n', '  File "/home/delano/working/fantasy/fantasy_py/calculation/regression/exe/do_meval.py", line 470, in eval_func\n    \'db\': meta_info.db_path.split(os.sep)[-1]})\n', '  File "/home/delano/working/fantasy/fantasy_py/util/hyper_param_tuning.py", line 893, in search\n    n_calls=self._iterations, n_random_starts=self._bayes_init_pts)\n', '  File "/home/delano/working/fantasy/venv/lib/python3.6/site-packages/skopt/optimizer/gp.py", line 228, in gp_minimize\n    callback=callback, n_jobs=n_jobs)\n', '  File "/home/delano/working/fantasy/venv/lib/python3.6/site-packages/skopt/optimizer/base.py", line 248, in base_minimize\n    next_y = func(next_x)\n', '  File "/home/delano/working/fantasy/fantasy_py/util/hyper_param_tuning.py", line 869, in skopt_func\n    self.errors[flattened_hp_dict] = (ex, traceback.format_stack())\n']
----------------------------------------


{'activation': 'sigmoid', 'dropout': 0.4559931972, 'hist_agg': 'none', 'layers': 2, 'learning_method': 'adagrad', 'n_cases': 8127, 'n_features': 388, 'n_games': 6, 'steps': 100, 'units': 59}
(sqlite3.OperationalError) unable to open database file (Background on this error at: http://sqlalche.me/e/e3q8)
['  File "scripts/meval.sc", line 3, in <module>\n    do_meval.process_cmd_line()\n', '  File "/home/delano/working/python_misc/ledona/__init__.py", line 19, in wrapper\n    result = timed_func(*args, **kwargs)\n', '  File "/home/delano/working/fantasy/fantasy_py/calculation/regression/exe/do_meval.py", line 562, in process_cmd_line\n    result = calc_engine.run_evaluation(eval_func)\n', '  File "/home/delano/working/fantasy/fantasy_py/calculation/engine.py", line 776, in run_evaluation\n    calc_def_id=calc_def_id)\n', '  File "/home/delano/working/fantasy/fantasy_py/calculation/engine.py", line 756, in calculate\n    **extra_kwargs)\n', '  File "/home/delano/working/fantasy/fantasy_py/calculation/regression/exe/do_meval.py", line 470, in eval_func\n    \'db\': meta_info.db_path.split(os.sep)[-1]})\n', '  File "/home/delano/working/fantasy/fantasy_py/util/hyper_param_tuning.py", line 893, in search\n    n_calls=self._iterations, n_random_starts=self._bayes_init_pts)\n', '  File "/home/delano/working/fantasy/venv/lib/python3.6/site-packages/skopt/optimizer/gp.py", line 228, in gp_minimize\n    callback=callback, n_jobs=n_jobs)\n', '  File "/home/delano/working/fantasy/venv/lib/python3.6/site-packages/skopt/optimizer/base.py", line 248, in base_minimize\n    next_y = func(next_x)\n', '  File "/home/delano/working/fantasy/fantasy_py/util/hyper_param_tuning.py", line 869, in skopt_func\n    self.errors[flattened_hp_dict] = (ex, traceback.format_stack())\n']
----------------------------------------


{'activation': 'relu', 'dropout': 0.3000015215, 'hist_agg': 'none', 'layers': 4, 'learning_method': 'adamax', 'n_cases': 500, 'n_features': 68, 'n_games': 1, 'steps': 600, 'units': 20}
(sqlite3.OperationalError) unable to open database file (Background on this error at: http://sqlalche.me/e/e3q8)
['  File "scripts/meval.sc", line 3, in <module>\n    do_meval.process_cmd_line()\n', '  File "/home/delano/working/python_misc/ledona/__init__.py", line 19, in wrapper\n    result = timed_func(*args, **kwargs)\n', '  File "/home/delano/working/fantasy/fantasy_py/calculation/regression/exe/do_meval.py", line 562, in process_cmd_line\n    result = calc_engine.run_evaluation(eval_func)\n', '  File "/home/delano/working/fantasy/fantasy_py/calculation/engine.py", line 776, in run_evaluation\n    calc_def_id=calc_def_id)\n', '  File "/home/delano/working/fantasy/fantasy_py/calculation/engine.py", line 756, in calculate\n    **extra_kwargs)\n', '  File "/home/delano/working/fantasy/fantasy_py/calculation/regression/exe/do_meval.py", line 470, in eval_func\n    \'db\': meta_info.db_path.split(os.sep)[-1]})\n', '  File "/home/delano/working/fantasy/fantasy_py/util/hyper_param_tuning.py", line 893, in search\n    n_calls=self._iterations, n_random_starts=self._bayes_init_pts)\n', '  File "/home/delano/working/fantasy/venv/lib/python3.6/site-packages/skopt/optimizer/gp.py", line 228, in gp_minimize\n    callback=callback, n_jobs=n_jobs)\n', '  File "/home/delano/working/fantasy/venv/lib/python3.6/site-packages/skopt/optimizer/base.py", line 248, in base_minimize\n    next_y = func(next_x)\n', '  File "/home/delano/working/fantasy/fantasy_py/util/hyper_param_tuning.py", line 869, in skopt_func\n    self.errors[flattened_hp_dict] = (ex, traceback.format_stack())\n']
----------------------------------------


{'activation': 'relu', 'dropout': 0.3727629394, 'hist_agg': 'none', 'layers': 5, 'learning_method': 'adagrad', 'n_cases': 7344, 'n_features': 324, 'n_games': 5, 'steps': 600, 'units': 68}
(sqlite3.OperationalError) unable to open database file (Background on this error at: http://sqlalche.me/e/e3q8)
['  File "scripts/meval.sc", line 3, in <module>\n    do_meval.process_cmd_line()\n', '  File "/home/delano/working/python_misc/ledona/__init__.py", line 19, in wrapper\n    result = timed_func(*args, **kwargs)\n', '  File "/home/delano/working/fantasy/fantasy_py/calculation/regression/exe/do_meval.py", line 562, in process_cmd_line\n    result = calc_engine.run_evaluation(eval_func)\n', '  File "/home/delano/working/fantasy/fantasy_py/calculation/engine.py", line 776, in run_evaluation\n    calc_def_id=calc_def_id)\n', '  File "/home/delano/working/fantasy/fantasy_py/calculation/engine.py", line 756, in calculate\n    **extra_kwargs)\n', '  File "/home/delano/working/fantasy/fantasy_py/calculation/regression/exe/do_meval.py", line 470, in eval_func\n    \'db\': meta_info.db_path.split(os.sep)[-1]})\n', '  File "/home/delano/working/fantasy/fantasy_py/util/hyper_param_tuning.py", line 893, in search\n    n_calls=self._iterations, n_random_starts=self._bayes_init_pts)\n', '  File "/home/delano/working/fantasy/venv/lib/python3.6/site-packages/skopt/optimizer/gp.py", line 228, in gp_minimize\n    callback=callback, n_jobs=n_jobs)\n', '  File "/home/delano/working/fantasy/venv/lib/python3.6/site-packages/skopt/optimizer/base.py", line 248, in base_minimize\n    next_y = func(next_x)\n', '  File "/home/delano/working/fantasy/fantasy_py/util/hyper_param_tuning.py", line 869, in skopt_func\n    self.errors[flattened_hp_dict] = (ex, traceback.format_stack())\n']
----------------------------------------


{'activation': 'sigmoid', 'dropout': 0.5136708539, 'hist_agg': 'none', 'layers': 1, 'learning_method': 'adam', 'n_cases': 7837, 'n_features': 132, 'n_games': 2, 'steps': 100, 'units': 35}
(sqlite3.OperationalError) unable to open database file (Background on this error at: http://sqlalche.me/e/e3q8)
['  File "scripts/meval.sc", line 3, in <module>\n    do_meval.process_cmd_line()\n', '  File "/home/delano/working/python_misc/ledona/__init__.py", line 19, in wrapper\n    result = timed_func(*args, **kwargs)\n', '  File "/home/delano/working/fantasy/fantasy_py/calculation/regression/exe/do_meval.py", line 562, in process_cmd_line\n    result = calc_engine.run_evaluation(eval_func)\n', '  File "/home/delano/working/fantasy/fantasy_py/calculation/engine.py", line 776, in run_evaluation\n    calc_def_id=calc_def_id)\n', '  File "/home/delano/working/fantasy/fantasy_py/calculation/engine.py", line 756, in calculate\n    **extra_kwargs)\n', '  File "/home/delano/working/fantasy/fantasy_py/calculation/regression/exe/do_meval.py", line 470, in eval_func\n    \'db\': meta_info.db_path.split(os.sep)[-1]})\n', '  File "/home/delano/working/fantasy/fantasy_py/util/hyper_param_tuning.py", line 893, in search\n    n_calls=self._iterations, n_random_starts=self._bayes_init_pts)\n', '  File "/home/delano/working/fantasy/venv/lib/python3.6/site-packages/skopt/optimizer/gp.py", line 228, in gp_minimize\n    callback=callback, n_jobs=n_jobs)\n', '  File "/home/delano/working/fantasy/venv/lib/python3.6/site-packages/skopt/optimizer/base.py", line 248, in base_minimize\n    next_y = func(next_x)\n', '  File "/home/delano/working/fantasy/fantasy_py/util/hyper_param_tuning.py", line 869, in skopt_func\n    self.errors[flattened_hp_dict] = (ex, traceback.format_stack())\n']
----------------------------------------


{'activation': 'tanh', 'dropout': 0.6642045071, 'hist_agg': 'none', 'layers': 4, 'learning_method': 'nadam', 'n_cases': 7067, 'n_features': 388, 'n_games': 6, 'steps': 400, 'units': 21}
(sqlite3.OperationalError) unable to open database file (Background on this error at: http://sqlalche.me/e/e3q8)
['  File "scripts/meval.sc", line 3, in <module>\n    do_meval.process_cmd_line()\n', '  File "/home/delano/working/python_misc/ledona/__init__.py", line 19, in wrapper\n    result = timed_func(*args, **kwargs)\n', '  File "/home/delano/working/fantasy/fantasy_py/calculation/regression/exe/do_meval.py", line 562, in process_cmd_line\n    result = calc_engine.run_evaluation(eval_func)\n', '  File "/home/delano/working/fantasy/fantasy_py/calculation/engine.py", line 776, in run_evaluation\n    calc_def_id=calc_def_id)\n', '  File "/home/delano/working/fantasy/fantasy_py/calculation/engine.py", line 756, in calculate\n    **extra_kwargs)\n', '  File "/home/delano/working/fantasy/fantasy_py/calculation/regression/exe/do_meval.py", line 470, in eval_func\n    \'db\': meta_info.db_path.split(os.sep)[-1]})\n', '  File "/home/delano/working/fantasy/fantasy_py/util/hyper_param_tuning.py", line 893, in search\n    n_calls=self._iterations, n_random_starts=self._bayes_init_pts)\n', '  File "/home/delano/working/fantasy/venv/lib/python3.6/site-packages/skopt/optimizer/gp.py", line 228, in gp_minimize\n    callback=callback, n_jobs=n_jobs)\n', '  File "/home/delano/working/fantasy/venv/lib/python3.6/site-packages/skopt/optimizer/base.py", line 248, in base_minimize\n    next_y = func(next_x)\n', '  File "/home/delano/working/fantasy/fantasy_py/util/hyper_param_tuning.py", line 869, in skopt_func\n    self.errors[flattened_hp_dict] = (ex, traceback.format_stack())\n']
----------------------------------------


{'activation': 'relu', 'dropout': 0.5893907678, 'hist_agg': 'none', 'layers': 4, 'learning_method': 'adagrad', 'n_cases': 26047, 'n_features': 132, 'n_games': 2, 'steps': 300, 'units': 34}
(sqlite3.OperationalError) unable to open database file (Background on this error at: http://sqlalche.me/e/e3q8)
['  File "scripts/meval.sc", line 3, in <module>\n    do_meval.process_cmd_line()\n', '  File "/home/delano/working/python_misc/ledona/__init__.py", line 19, in wrapper\n    result = timed_func(*args, **kwargs)\n', '  File "/home/delano/working/fantasy/fantasy_py/calculation/regression/exe/do_meval.py", line 562, in process_cmd_line\n    result = calc_engine.run_evaluation(eval_func)\n', '  File "/home/delano/working/fantasy/fantasy_py/calculation/engine.py", line 776, in run_evaluation\n    calc_def_id=calc_def_id)\n', '  File "/home/delano/working/fantasy/fantasy_py/calculation/engine.py", line 756, in calculate\n    **extra_kwargs)\n', '  File "/home/delano/working/fantasy/fantasy_py/calculation/regression/exe/do_meval.py", line 470, in eval_func\n    \'db\': meta_info.db_path.split(os.sep)[-1]})\n', '  File "/home/delano/working/fantasy/fantasy_py/util/hyper_param_tuning.py", line 893, in search\n    n_calls=self._iterations, n_random_starts=self._bayes_init_pts)\n', '  File "/home/delano/working/fantasy/venv/lib/python3.6/site-packages/skopt/optimizer/gp.py", line 228, in gp_minimize\n    callback=callback, n_jobs=n_jobs)\n', '  File "/home/delano/working/fantasy/venv/lib/python3.6/site-packages/skopt/optimizer/base.py", line 248, in base_minimize\n    next_y = func(next_x)\n', '  File "/home/delano/working/fantasy/fantasy_py/util/hyper_param_tuning.py", line 869, in skopt_func\n    self.errors[flattened_hp_dict] = (ex, traceback.format_stack())\n']
----------------------------------------


{'activation': 'relu', 'dropout': 0.5075124042, 'hist_agg': 'none', 'layers': 3, 'learning_method': 'adam', 'n_cases': 15560, 'n_features': 260, 'n_games': 4, 'steps': 800, 'units': 33}
(sqlite3.OperationalError) unable to open database file (Background on this error at: http://sqlalche.me/e/e3q8)
['  File "scripts/meval.sc", line 3, in <module>\n    do_meval.process_cmd_line()\n', '  File "/home/delano/working/python_misc/ledona/__init__.py", line 19, in wrapper\n    result = timed_func(*args, **kwargs)\n', '  File "/home/delano/working/fantasy/fantasy_py/calculation/regression/exe/do_meval.py", line 562, in process_cmd_line\n    result = calc_engine.run_evaluation(eval_func)\n', '  File "/home/delano/working/fantasy/fantasy_py/calculation/engine.py", line 776, in run_evaluation\n    calc_def_id=calc_def_id)\n', '  File "/home/delano/working/fantasy/fantasy_py/calculation/engine.py", line 756, in calculate\n    **extra_kwargs)\n', '  File "/home/delano/working/fantasy/fantasy_py/calculation/regression/exe/do_meval.py", line 470, in eval_func\n    \'db\': meta_info.db_path.split(os.sep)[-1]})\n', '  File "/home/delano/working/fantasy/fantasy_py/util/hyper_param_tuning.py", line 893, in search\n    n_calls=self._iterations, n_random_starts=self._bayes_init_pts)\n', '  File "/home/delano/working/fantasy/venv/lib/python3.6/site-packages/skopt/optimizer/gp.py", line 228, in gp_minimize\n    callback=callback, n_jobs=n_jobs)\n', '  File "/home/delano/working/fantasy/venv/lib/python3.6/site-packages/skopt/optimizer/base.py", line 248, in base_minimize\n    next_y = func(next_x)\n', '  File "/home/delano/working/fantasy/fantasy_py/util/hyper_param_tuning.py", line 869, in skopt_func\n    self.errors[flattened_hp_dict] = (ex, traceback.format_stack())\n']
----------------------------------------


{'activation': 'relu', 'dropout': 0.3100346818, 'hist_agg': 'none', 'layers': 4, 'learning_method': 'adam', 'n_cases': 40000, 'n_features': 452, 'n_games': 7, 'steps': 300, 'units': 90}
(sqlite3.OperationalError) unable to open database file (Background on this error at: http://sqlalche.me/e/e3q8)
['  File "scripts/meval.sc", line 3, in <module>\n    do_meval.process_cmd_line()\n', '  File "/home/delano/working/python_misc/ledona/__init__.py", line 19, in wrapper\n    result = timed_func(*args, **kwargs)\n', '  File "/home/delano/working/fantasy/fantasy_py/calculation/regression/exe/do_meval.py", line 562, in process_cmd_line\n    result = calc_engine.run_evaluation(eval_func)\n', '  File "/home/delano/working/fantasy/fantasy_py/calculation/engine.py", line 776, in run_evaluation\n    calc_def_id=calc_def_id)\n', '  File "/home/delano/working/fantasy/fantasy_py/calculation/engine.py", line 756, in calculate\n    **extra_kwargs)\n', '  File "/home/delano/working/fantasy/fantasy_py/calculation/regression/exe/do_meval.py", line 470, in eval_func\n    \'db\': meta_info.db_path.split(os.sep)[-1]})\n', '  File "/home/delano/working/fantasy/fantasy_py/util/hyper_param_tuning.py", line 893, in search\n    n_calls=self._iterations, n_random_starts=self._bayes_init_pts)\n', '  File "/home/delano/working/fantasy/venv/lib/python3.6/site-packages/skopt/optimizer/gp.py", line 228, in gp_minimize\n    callback=callback, n_jobs=n_jobs)\n', '  File "/home/delano/working/fantasy/venv/lib/python3.6/site-packages/skopt/optimizer/base.py", line 248, in base_minimize\n    next_y = func(next_x)\n', '  File "/home/delano/working/fantasy/fantasy_py/util/hyper_param_tuning.py", line 869, in skopt_func\n    self.errors[flattened_hp_dict] = (ex, traceback.format_stack())\n']
----------------------------------------


{'activation': 'relu', 'dropout': 0.5047514892, 'hist_agg': 'none', 'layers': 5, 'learning_method': 'adadelta', 'n_cases': 500, 'n_features': 132, 'n_games': 2, 'steps': 500, 'units': 38}
(sqlite3.OperationalError) unable to open database file (Background on this error at: http://sqlalche.me/e/e3q8)
['  File "scripts/meval.sc", line 3, in <module>\n    do_meval.process_cmd_line()\n', '  File "/home/delano/working/python_misc/ledona/__init__.py", line 19, in wrapper\n    result = timed_func(*args, **kwargs)\n', '  File "/home/delano/working/fantasy/fantasy_py/calculation/regression/exe/do_meval.py", line 562, in process_cmd_line\n    result = calc_engine.run_evaluation(eval_func)\n', '  File "/home/delano/working/fantasy/fantasy_py/calculation/engine.py", line 776, in run_evaluation\n    calc_def_id=calc_def_id)\n', '  File "/home/delano/working/fantasy/fantasy_py/calculation/engine.py", line 756, in calculate\n    **extra_kwargs)\n', '  File "/home/delano/working/fantasy/fantasy_py/calculation/regression/exe/do_meval.py", line 470, in eval_func\n    \'db\': meta_info.db_path.split(os.sep)[-1]})\n', '  File "/home/delano/working/fantasy/fantasy_py/util/hyper_param_tuning.py", line 893, in search\n    n_calls=self._iterations, n_random_starts=self._bayes_init_pts)\n', '  File "/home/delano/working/fantasy/venv/lib/python3.6/site-packages/skopt/optimizer/gp.py", line 228, in gp_minimize\n    callback=callback, n_jobs=n_jobs)\n', '  File "/home/delano/working/fantasy/venv/lib/python3.6/site-packages/skopt/optimizer/base.py", line 248, in base_minimize\n    next_y = func(next_x)\n', '  File "/home/delano/working/fantasy/fantasy_py/util/hyper_param_tuning.py", line 869, in skopt_func\n    self.errors[flattened_hp_dict] = (ex, traceback.format_stack())\n']
----------------------------------------


{'activation': 'relu', 'dropout': 0.608330905, 'hist_agg': 'none', 'layers': 1, 'learning_method': 'adagrad', 'n_cases': 11354, 'n_features': 196, 'n_games': 3, 'steps': 600, 'units': 86}
(sqlite3.OperationalError) unable to open database file (Background on this error at: http://sqlalche.me/e/e3q8)
['  File "scripts/meval.sc", line 3, in <module>\n    do_meval.process_cmd_line()\n', '  File "/home/delano/working/python_misc/ledona/__init__.py", line 19, in wrapper\n    result = timed_func(*args, **kwargs)\n', '  File "/home/delano/working/fantasy/fantasy_py/calculation/regression/exe/do_meval.py", line 562, in process_cmd_line\n    result = calc_engine.run_evaluation(eval_func)\n', '  File "/home/delano/working/fantasy/fantasy_py/calculation/engine.py", line 776, in run_evaluation\n    calc_def_id=calc_def_id)\n', '  File "/home/delano/working/fantasy/fantasy_py/calculation/engine.py", line 756, in calculate\n    **extra_kwargs)\n', '  File "/home/delano/working/fantasy/fantasy_py/calculation/regression/exe/do_meval.py", line 470, in eval_func\n    \'db\': meta_info.db_path.split(os.sep)[-1]})\n', '  File "/home/delano/working/fantasy/fantasy_py/util/hyper_param_tuning.py", line 893, in search\n    n_calls=self._iterations, n_random_starts=self._bayes_init_pts)\n', '  File "/home/delano/working/fantasy/venv/lib/python3.6/site-packages/skopt/optimizer/gp.py", line 228, in gp_minimize\n    callback=callback, n_jobs=n_jobs)\n', '  File "/home/delano/working/fantasy/venv/lib/python3.6/site-packages/skopt/optimizer/base.py", line 248, in base_minimize\n    next_y = func(next_x)\n', '  File "/home/delano/working/fantasy/fantasy_py/util/hyper_param_tuning.py", line 869, in skopt_func\n    self.errors[flattened_hp_dict] = (ex, traceback.format_stack())\n']
----------------------------------------


{'activation': 'sigmoid', 'dropout': 0.3723192454, 'hist_agg': 'none', 'layers': 2, 'learning_method': 'nadam', 'n_cases': 4850, 'n_features': 388, 'n_games': 6, 'steps': 500, 'units': 90}
(sqlite3.OperationalError) unable to open database file (Background on this error at: http://sqlalche.me/e/e3q8)
['  File "scripts/meval.sc", line 3, in <module>\n    do_meval.process_cmd_line()\n', '  File "/home/delano/working/python_misc/ledona/__init__.py", line 19, in wrapper\n    result = timed_func(*args, **kwargs)\n', '  File "/home/delano/working/fantasy/fantasy_py/calculation/regression/exe/do_meval.py", line 562, in process_cmd_line\n    result = calc_engine.run_evaluation(eval_func)\n', '  File "/home/delano/working/fantasy/fantasy_py/calculation/engine.py", line 776, in run_evaluation\n    calc_def_id=calc_def_id)\n', '  File "/home/delano/working/fantasy/fantasy_py/calculation/engine.py", line 756, in calculate\n    **extra_kwargs)\n', '  File "/home/delano/working/fantasy/fantasy_py/calculation/regression/exe/do_meval.py", line 470, in eval_func\n    \'db\': meta_info.db_path.split(os.sep)[-1]})\n', '  File "/home/delano/working/fantasy/fantasy_py/util/hyper_param_tuning.py", line 893, in search\n    n_calls=self._iterations, n_random_starts=self._bayes_init_pts)\n', '  File "/home/delano/working/fantasy/venv/lib/python3.6/site-packages/skopt/optimizer/gp.py", line 228, in gp_minimize\n    callback=callback, n_jobs=n_jobs)\n', '  File "/home/delano/working/fantasy/venv/lib/python3.6/site-packages/skopt/optimizer/base.py", line 248, in base_minimize\n    next_y = func(next_x)\n', '  File "/home/delano/working/fantasy/fantasy_py/util/hyper_param_tuning.py", line 869, in skopt_func\n    self.errors[flattened_hp_dict] = (ex, traceback.format_stack())\n']
----------------------------------------


{'activation': 'sigmoid', 'dropout': 0.5910855199, 'hist_agg': 'none', 'layers': 2, 'learning_method': 'adam', 'n_cases': 17054, 'n_features': 324, 'n_games': 5, 'steps': 800, 'units': 96}
(sqlite3.OperationalError) unable to open database file (Background on this error at: http://sqlalche.me/e/e3q8)
['  File "scripts/meval.sc", line 3, in <module>\n    do_meval.process_cmd_line()\n', '  File "/home/delano/working/python_misc/ledona/__init__.py", line 19, in wrapper\n    result = timed_func(*args, **kwargs)\n', '  File "/home/delano/working/fantasy/fantasy_py/calculation/regression/exe/do_meval.py", line 562, in process_cmd_line\n    result = calc_engine.run_evaluation(eval_func)\n', '  File "/home/delano/working/fantasy/fantasy_py/calculation/engine.py", line 776, in run_evaluation\n    calc_def_id=calc_def_id)\n', '  File "/home/delano/working/fantasy/fantasy_py/calculation/engine.py", line 756, in calculate\n    **extra_kwargs)\n', '  File "/home/delano/working/fantasy/fantasy_py/calculation/regression/exe/do_meval.py", line 470, in eval_func\n    \'db\': meta_info.db_path.split(os.sep)[-1]})\n', '  File "/home/delano/working/fantasy/fantasy_py/util/hyper_param_tuning.py", line 893, in search\n    n_calls=self._iterations, n_random_starts=self._bayes_init_pts)\n', '  File "/home/delano/working/fantasy/venv/lib/python3.6/site-packages/skopt/optimizer/gp.py", line 228, in gp_minimize\n    callback=callback, n_jobs=n_jobs)\n', '  File "/home/delano/working/fantasy/venv/lib/python3.6/site-packages/skopt/optimizer/base.py", line 248, in base_minimize\n    next_y = func(next_x)\n', '  File "/home/delano/working/fantasy/fantasy_py/util/hyper_param_tuning.py", line 869, in skopt_func\n    self.errors[flattened_hp_dict] = (ex, traceback.format_stack())\n']
----------------------------------------


{'activation': 'sigmoid', 'dropout': 0.3238756467, 'hist_agg': 'none', 'layers': 2, 'learning_method': 'adagrad', 'n_cases': 6229, 'n_features': 196, 'n_games': 3, 'steps': 400, 'units': 66}
(sqlite3.OperationalError) unable to open database file (Background on this error at: http://sqlalche.me/e/e3q8)
['  File "scripts/meval.sc", line 3, in <module>\n    do_meval.process_cmd_line()\n', '  File "/home/delano/working/python_misc/ledona/__init__.py", line 19, in wrapper\n    result = timed_func(*args, **kwargs)\n', '  File "/home/delano/working/fantasy/fantasy_py/calculation/regression/exe/do_meval.py", line 562, in process_cmd_line\n    result = calc_engine.run_evaluation(eval_func)\n', '  File "/home/delano/working/fantasy/fantasy_py/calculation/engine.py", line 776, in run_evaluation\n    calc_def_id=calc_def_id)\n', '  File "/home/delano/working/fantasy/fantasy_py/calculation/engine.py", line 756, in calculate\n    **extra_kwargs)\n', '  File "/home/delano/working/fantasy/fantasy_py/calculation/regression/exe/do_meval.py", line 470, in eval_func\n    \'db\': meta_info.db_path.split(os.sep)[-1]})\n', '  File "/home/delano/working/fantasy/fantasy_py/util/hyper_param_tuning.py", line 893, in search\n    n_calls=self._iterations, n_random_starts=self._bayes_init_pts)\n', '  File "/home/delano/working/fantasy/venv/lib/python3.6/site-packages/skopt/optimizer/gp.py", line 228, in gp_minimize\n    callback=callback, n_jobs=n_jobs)\n', '  File "/home/delano/working/fantasy/venv/lib/python3.6/site-packages/skopt/optimizer/base.py", line 248, in base_minimize\n    next_y = func(next_x)\n', '  File "/home/delano/working/fantasy/fantasy_py/util/hyper_param_tuning.py", line 869, in skopt_func\n    self.errors[flattened_hp_dict] = (ex, traceback.format_stack())\n']
----------------------------------------


