{'est': 'ols', 'hist_agg': 'median', 'n_cases': 3663, 'n_features': 36, 'n_games': 3}
('Feature selection failure on fit! This could be due to running feature selection on players without valid score for output stat. For example draftkings does not score Kickers.', LinAlgError('SVD did not converge',))
['  File "/Users/delano/working/fantasy/venv/bin/ipython", line 11, in <module>\n    sys.exit(start_ipython())\n', '  File "/Users/delano/working/fantasy/venv/lib/python3.6/site-packages/IPython/__init__.py", line 125, in start_ipython\n    return launch_new_instance(argv=argv, **kwargs)\n', '  File "/Users/delano/working/fantasy/venv/lib/python3.6/site-packages/traitlets/config/application.py", line 657, in launch_instance\n    app.initialize(argv)\n', '  File "<decorator-gen-112>", line 2, in initialize\n', '  File "/Users/delano/working/fantasy/venv/lib/python3.6/site-packages/traitlets/config/application.py", line 87, in catch_config_error\n    return method(app, *args, **kwargs)\n', '  File "/Users/delano/working/fantasy/venv/lib/python3.6/site-packages/IPython/terminal/ipapp.py", line 323, in initialize\n    self.init_code()\n', '  File "/Users/delano/working/fantasy/venv/lib/python3.6/site-packages/IPython/core/shellapp.py", line 271, in init_code\n    self._run_cmd_line_code()\n', '  File "/Users/delano/working/fantasy/venv/lib/python3.6/site-packages/IPython/core/shellapp.py", line 391, in _run_cmd_line_code\n    self._exec_file(fname, shell_futures=True)\n', '  File "/Users/delano/working/fantasy/venv/lib/python3.6/site-packages/IPython/core/shellapp.py", line 323, in _exec_file\n    raise_exceptions=True)\n', '  File "/Users/delano/working/fantasy/venv/lib/python3.6/site-packages/IPython/core/interactiveshell.py", line 2527, in safe_execfile\n    self.compile if shell_futures else None)\n', '  File "/Users/delano/working/fantasy/venv/lib/python3.6/site-packages/IPython/utils/py3compat.py", line 188, in execfile\n    exec(compiler(f.read(), fname, \'exec\'), glob, loc)\n', '  File "/Users/delano/working/fantasy/scripts/meval.sc", line 3, in <module>\n    do_meval.process_cmd_line()\n', '  File "/Users/delano/working/python_misc/ledona/__init__.py", line 19, in wrapper\n    result = timed_func(*args, **kwargs)\n', '  File "/Users/delano/working/fantasy/fantasy_py/calculation/regression/exe/do_meval.py", line 563, in process_cmd_line\n    except ResumeNotPossible as ex:\n', '  File "/Users/delano/working/fantasy/fantasy_py/calculation/engine.py", line 776, in run_evaluation\n    calc_def_id=calc_def_id)\n', '  File "/Users/delano/working/fantasy/fantasy_py/calculation/engine.py", line 756, in calculate\n    **extra_kwargs)\n', '  File "/Users/delano/working/fantasy/fantasy_py/calculation/regression/exe/do_meval.py", line 474, in eval_func\n', '  File "/Users/delano/working/fantasy/fantasy_py/util/hyper_param_tuning.py", line 879, in search\n    n_calls=self._iterations, n_random_starts=self._bayes_init_pts)\n', '  File "/Users/delano/working/fantasy/venv/lib/python3.6/site-packages/skopt/optimizer/gp.py", line 228, in gp_minimize\n    callback=callback, n_jobs=n_jobs)\n', '  File "/Users/delano/working/fantasy/venv/lib/python3.6/site-packages/skopt/optimizer/base.py", line 248, in base_minimize\n    next_y = func(next_x)\n', '  File "/Users/delano/working/fantasy/fantasy_py/util/hyper_param_tuning.py", line 855, in skopt_func\n    self.errors[flattened_hp_dict] = (ex, traceback.format_stack())\n']
----------------------------------------


